Workbook

Sheet Справка
A1: Справка — как пользоваться ведомостью
A3: Полное описание правил — в файле grading-system.md / .pdf рядом с этой таблицей. Здесь — краткая шпаргалка.
A5: 1. На листе «Настройки» заданы веса лаб, пороги чек-листа по потокам, штрафы за защиту и просрочку. Их можно менять — все формулы на «Ведомости» ссылаются туда.
A6: 2. На листе «Ведомость» — по одной строке на студента. Жёлтые ячейки заполняются вручную:
A7: • Поток — ТТП или ТТМ (выбор из списка).
A8: • Чек-лист — сколько пунктов «Критерии сдачи» лабы выполнено (просто число, из скольких — написано на «Настройках»).
A9: • Git (только Лабы 1-5) — использовал ли студент git по-настоящему (несколько содержательных коммитов, не один дамп) — Да/Нет.
A10: • Защита — Уверенно / Частично / Не может объяснить — по итогам ответов на 2-3 контрольных вопроса лабы.
A11: • Недель просрочки — 0, если сдано в срок (2 недели на лабу); иначе 1, 2 или 3 (3 = «3 и более»).
A12: 3. Серые ячейки (Тир, Баллы, Итого, Оценка) считаются сами — их трогать не нужно.
A13: 4. Две первые строки — примеры (Иванов И.И. — ТТП, Петрова П.П. — ТТМ), показывают разные тиры и граничные случаи. Замените на реальных студентов или добавьте новые строки ниже (формулы нужно будет протянуть вниз, выделив последнюю заполненную строку с формулами и потянув за уголок).
A15: Ключевое правило, которое легко забыть: у ТТП без Git тир не выше 3, и даже тройка требует 100% чек-листа — при неполном чек-листе без git сразу тир 2, а не 3.
... A17: 6. Итого баллов теперь может быть больше 100, если взята бонусная Лаба 6 — это ожидаемо, оценка всё равно не выше 5 (порог 90+).

Sheet Настройки
A1: Настройки БРС — ПИОГИ, 3 семестр
A2: Меняйте только жёлтые ячейки. Формулы на листе «Ведомость» ссылаются на эти таблицы.
A4: Баллы и чек-листы по лабам
A5: Лаба | B5: Вес (баллов) | C5: Пунктов в чек-листе
A6: 0. Git и фигуры | B6: 10 | C6: 10
A7: 1. Редактор противников | B7: 15 | C7: 8
A8: 2. Инкапсуляция | B8: 20 | C8: 9
A9: 3. Абстракция/наследование/полиморфизм | B9: 20 | C9: 7
A10: 4. Интерфейсы | B10: 20 | C10: 7
A11: 5. Делегаты и события | B11: 15 | C11: 6
A12: Итого | B12: =SUM(B6:B11) -> 100
A14: Тиры — % от баллов лабы
A15: Тир | B15: % баллов
A16: 5 | B16: 1
A17: 4 | B17: 0.85
A18: 3 | B18: 0.65
A19: 2 | B19: 0
A21: Пороги чек-листа, % (ТТП)
A22: Тир | B22: Порог, %
A23: 5 | B23: 1
A24: 4 | B24: 0.85
A25: 3 | B25: 0.65
A27: Пороги чек-листа, % (ТТМ)
A28: Тир | B28: Порог, %
A29: 5 | B29: 0.9
A30: 4 | B30: 0.75
A31: 3 | B31: 0.5
A33: Потолок тира — защита
A34: Защита | B34: Потолок тира
A35: Уверенно | B35: 5
A36: Частично | B36: 4
A37: Не может объяснить | B37: 2
A39: Потолок тира — просрочка (недель сверх дедлайна)
A40: Недель просрочки | B40: Потолок тира
A41: 0 | B41: 5
A42: 1 | B42: 4
A43: 2 | B43: 3
A44: 3 | B44: 2
A46: Итоговая оценка за семестр
A47: Мин. баллов | B47: Оценка
...

Sheet Ведомость
A1: Ведомость — ПИОГИ, 3 семестр
A2: Жёлтые ячейки — вносите вручную (чек-лист, git, защита, недели просрочки). Серые ячейки — считаются автоматически по формулам, не редактируйте их. Лаба 0 без отдельного столбца git — использование git там уже часть самого чек-листа.
A4: Студент | B4: Поток | C4: Лаба 0 | H4: Лаба 1 | N4: Лаба 2 | T4: Лаба 3 | Z4: Лаба 4 | AF4: Лаба 5 | AL4: Лаба 6 (бонус) | AQ4: Итого баллов | AR4: Оценка
C5: Чек-лист (из 10) | D5: Защита | E5: Недель просрочки | F5: Тир | G5: Баллы | H5: Чек-лист (из 8) | I5: Git (1-5) | J5: Защита | K5: Недель просрочки | L5: Тир | M5: Баллы | N5: Чек-лист (из 9) | O5: Git (1-5) | P5: Защита | Q5: Недель просрочки | R5: Тир | S5: Баллы | T5: Чек-лист (из 7) | U5: Git (1-5) | V5: Защита | W5: Недель просрочки | X5: Тир | Y5: Баллы | Z5: Чек-лист (из 7) | AA5: Git (1-5) | AB5: Защита | AC5: Недель просрочки | AD5: Тир | AE5: Баллы | AF5: Чек-лист (из 6) | AG5: Git (1-5) | AH5: Защита | AI5: Недель просрочки | AJ5: Тир | AK5: Баллы | AN5: Защита | AO5: Тир | AP5: Баллы
A6: Иванов И.И. (пример) | B6: ТТП | C6: 10 | D6: Уверенно | E6: 0 | F6: =IF(OR($A6="",C6=""),"",MIN(IF($B6="ТТП",IF(C6/Настройки!$C$6>=Настройки!$B$23,5,IF(C6/Настройки!$C$6>=Настройки!$B$24,4,IF(C6/Настройки!$C$6>=Настройки!$B$25,3,2))),IF($B6="ТТМ",IF(C6/Настройки!$C$6>=Настройки!$B$29,5,IF(C6/Настройки!$C$6>=Настройки!$B$30,4,IF(C6/Настройки!$C$6>=Настройки!$B$31,3,2))),"")),IFERROR(VLOOKUP(D6,Настройки!$A$35:$B$37,2,FALSE()),5),IFERROR(VLOOKUP(E6,Настройки!$A$41:$B$44,2,FALSE()),5))) -> 5 | G6: =IF(F6="","",Настройки!$B$6*VLOOKUP(F6,Настройки!$A$16:$B$19,2,FALSE())) -> 10 | H6: 8 | I6: Да | J6: Уверенно | K6: 0 | L6: =IF(OR($A6="",H6=""),"",MIN(IF($B6="ТТП",IF(H6/Настройки!$C$7>=Настройки!$B$23,5,IF(H6/Настройки!$C$7>=Настройки!$B$24,4,IF(H6/Настройки!$C$7>=Настройки!$B$25,3,2))),IF($B6="ТТМ",IF(H6/Настройки!$C$7>=Настройки!$B$29,5,IF(H6/Настройки!$C$7>=Настройки!$B$30,4,IF(H6/Настройки!$C$7>=Настройки!$B$31,3,2))),"")),IF($B6<>"ТТП",5,IF(I6="Да",5,4)),IFERROR(VLOOKUP(J6,Настройки!$A$35:$B$37,2,FALSE()),5),IFERROR(VLOOKUP(K6,Настройки!$A$41:$B$44,2,FALSE()),5))) -> 5 | M6: =IF(L6="","",MIN(Настройки!$B$7,Настройки!$B$7*VLOOKUP(L6,Настройки!$A$16:$B$19,2,FALSE())+IF(AND($B6="ТТМ",I6="Да"),Настройки!$B$7*Настройки!$A$53,0))) -> 15 | N6: 9 | O6: Да | P6: Уверенно | Q6: 0 | R6: =IF(OR($A6="",N6=""),"",MIN(IF($B6="ТТП",IF(N6/Настройки!$C$8>=Настройки!$B$23,5,IF(N6/Настройки!$C$8>=Настройки!$B$24,4,IF(N6/Настройки!$C$8>=Настройки!$B$25,3,2))),IF($B6="ТТМ",IF(N6/Настройки!$C$8>=Настройки!$B$29,5,IF(N6/Настройки!$C$8>=Настройки!$B$30,4,IF(N6/Настройки!$C$8>=Настройки!$B$31,3,2))),"")),IF($B6<>"ТТП",5,IF(O6="Да",5,4)),IFERROR(VLOOKUP(P6,Настройки!$A$35:$B$37,2,FALSE()),5),IFERROR(VLOOKUP(Q6,Настройки!$A$41:$B$44,2,FALSE()),5))) -> 5 | S6: =IF(R6="","",MIN(Настройки!$B$8,Настройки!$B$8*VLOOKUP(R6,Настройки!$A$16:$B$19,2,FALSE())+IF(AND($B6="ТТМ",O6="Да"),Настройки!$B$8*Настройки!$A$53,0))) -> 20 | T6: 7 | U6: Нет | V6: Уверенно | W6: 0 | X6: =IF(OR($A6="",T6=""),"",MIN(IF($B6="ТТП",IF(T6/Настройки!$C$9>=Настройки!$B$23,5,IF(T6/Настройки!$C$9>=Настройки!$B$24,4,IF(T6/Настройки!$C$9>=Настройки!$B$25,3,2))),IF($B6="ТТМ",IF(T6/Настройки!$C$9>=Настройки!$B$29,5,IF(T6/Настройки!$C$9>=Настройки!$B$30,4,IF(T6/Настройки!$C$9>=Настройки!$B$31,3,2))),"")),IF($B6<>"ТТП",5,IF(U6="Да",5,4)),IFERROR(VLOOKUP(V6,Настройки!$A$35:$B$37,2,FALSE()),5),IFERROR(VLOOKUP(W6,Настройки!$A$41:$B$44,2,FALSE()),5))) -> 4 | Y6: =IF(X6="","",MIN(Настройки!$B$9,Настройки!$B$9*VLOOKUP(X6,Настройки!$A$16:$B$19,2,FALSE())+IF(AND($B6="ТТМ",U6="Да"),Настройки!$B$9*Настройки!$A$53,0))) -> 17 | Z6: 5 | AA6: Да | AB6: Частично | AC6: 1 | AD6: =IF(OR($A6="",Z6=""),"",MIN(IF($B6="ТТП",IF(Z6/Настройки!$C$10>=Настройки!$B$23,5,IF(Z6/Настройки!$C$10>=Настройки!$B$24,4,IF(Z6/Настройки!$C$10>=Настройки!$B$25,3,2))),IF($B6="ТТМ",IF(Z6/Настройки!$C$10>=Настройки!$B$29,5,IF(Z6/Настройки!$C$10>=Настройки!$B$30,4,IF(Z6/Настройки!$C$10>=Настройки!$B$31,3,2))),"")),IF($B6<>"ТТП",5,IF(AA6="Да",5,4)),IFERROR(VLOOKUP(AB6,Настройки!$A$35:$B$37,2,FALSE()),5),IFERROR(VLOOKUP(AC6,Настройки!$A$41:$B$44,2,FALSE()),5))) -> 3 | AE6: =IF(AD6="","",MIN(Настройки!$B$10,Настройки!$B$10*VLOOKUP(AD6,Настройки!$A$16:$B$19,2,FALSE())+IF(AND($B6="ТТМ",AA6="Да"),Настройки!$B$10*Настройки!$A$53,0))) -> 13 | AF6: 3 | AG6: Нет | AH6: Не может объяснить | AI6: 3 | AJ6: =IF(OR($A6="",AF6=""),"",MIN(IF($B6="ТТП",IF(AF6/Настройки!$C$11>=Настройки!$B$23,5,IF(AF6/Настройки!$C$11>=Настройки!$B$24,4,IF(AF6/Настройки!$C$11>=Настройки!$B$25,3,2))),IF($B6="ТТМ",IF(AF6/Настройки!$C$11>=Настройки!$B$29,5,IF(AF6/Настройки!$C$11>=Настройки!$B$30,4,IF(AF6/Настройки!$C$11>=Настройки!$B$31,3,2))),"")),IF($B6<>"ТТП",5,IF(AG6="Да",5,4)),IFERROR(VLOOKUP(AH6,Настройки!$A$35:$B$37,2,FALSE()),5),IFERROR(VLOOKUP(AI6,Настройки!$A$41:$B$44,2,FALSE()),5))) -> 2 | AK6: =IF(AJ6="","",MIN(Настройки!$B$11,Настройки!$B$11*VLOOKUP(AJ6,Настройки!$A$16:$B$19,2,FALSE())+IF(AND($B6="ТТМ",AG6="Да"),Настройки!$B$11*Настройки!$A$53,0))) -> 0 | AL6: 9 | AM6: Да | AN6: Уверенно | AO6: =IF(OR($A6="",AL6=""),"",MIN(IF($B6="ТТП",IF(AL6/Настройки!$C$57>=Настройки!$B$23,5,IF(AL6/Настройки!$C$57>=Настройки!$B$24,4,IF(AL6/Настройки!$C$57>=Настройки!$B$25,3,2))),IF($B6="ТТМ",IF(AL6/Настройки!$C$57>=Настройки!$B$29,5,IF(AL6/Настройки!$C$57>=Настройки!$B$30,4,IF(AL6/Настройки!$C$57>=Настройки!$B$31,3,2))),"")),IF($B6<>"ТТП",5,IF(AM6="Да",5,4)),IFERROR(VLOOKUP(AN6,Настройки!$A$35:$B$37,2,FALSE()),5))) -> 5 | AP6: =IF(AO6="","",MIN(Настройки!$B$57,Настройки!$B$57*VLOOKUP(AO6,Настройки!$A$16:$B$19,2,FALSE())+IF(AND($B6="ТТМ",AM6="Да"),Настройки!$B$57*Настройки!$A$53,0))) -> 10 | AQ6: =IF($A6="","",SUM(G6,M6,S6,Y6,AE6,AK6)+IF(AP6="",0,AP6)) -> 85 | AR6: =IF(AQ6="","",VLOOKUP(AQ6,Настройки!$A$48:$B$51,2,TRUE())) -> 4
A7: Петрова П.П. (пример) | B7: ТТМ | C7: 9 | D7: Уверенно | E7: 0 | F7: =IF(OR($A7="",C7=""),"",MIN(IF($B7="ТТП",IF(C7/Настройки!$C$6>=Настройки!$B$23,5,IF(C7/Настройки!$C$6>=Настройки!$B$24,4,IF(C7/Настройки!$C$6>=Настройки!$B$25,3,2))),IF($B7="ТТМ",IF(C7/Настройки!$C$6>=Настройки!$B$29,5,IF(C7/Настройки!$C$6>=Настройки!$B$30,4,IF(C7/Настройки!$C$6>=Настройки!$B$31,3,2))),"")),IFERROR(VLOOKUP(D7,Настройки!$A$35:$B$37,2,FALSE()),5),IFERROR(VLOOKUP(E7,Настройки!$A$41:$B$44,2,FALSE()),5))) -> 5 | G7: =IF(F7="","",Настройки!$B$6*VLOOKUP(F7,Настройки!$A$16:$B$19,2,FALSE())) -> 10 | H7: 6 | I7: Нет | J7: Уверенно | K7: 0 | L7: =IF(OR($A7="",H7=""),"",MIN(IF($B7="ТТП",IF(H7/Настройки!$C$7>=Настройки!$B$23,5,IF(H7/Настройки!$C$7>=Настройки!$B$24,4,IF(H7/Настройки!$C$7>=Настройки!$B$25,3,2))),IF($B7="ТТМ",IF(H7/Настройки!$C$7>=Настройки!$B$29,5,IF(H7/Настройки!$C$7>=Настройки!$B$30,4,IF(H7/Настройки!$C$7>=Настройки!$B$31,3,2))),"")),IF($B7<>"ТТП",5,IF(I7="Да",5,4)),IFERROR(VLOOKUP(J7,Настройки!$A$35:$B$37,2,FALSE()),5),IFERROR(VLOOKUP(K7,Настройки!$A$41:$B$44,2,FALSE()),5))) -> 4 | M7: =IF(L7="","",MIN(Настройки!$B$7,Настройки!$B$7*VLOOKUP(L7,Настройки!$A$16:$B$19,2,FALSE())+IF(AND($B7="ТТМ",I7="Да"),Настройки!$B$7*Настройки!$A$53,0))) -> 12.75 | N7: 8 | O7: Да | P7: Уверенно | Q7: 0 | R7: =IF(OR($A7="",N7=""),"",MIN(IF($B7="ТТП",IF(N7/Настройки!$C$8>=Настройки!$B$23,5,IF(N7/Настройки!$C$8>=Настройки!$B$24,4,IF(N7/Настройки!$C$8>=Настройки!$B$25,3,2))),IF($B7="ТТМ",IF(N7/Настройки!$C$8>=Настройки!$B$29,5,IF(N7/Настройки!$C$8>=Настройки!$B$30,4,IF(N7/Настройки!$C$8>=Настройки!$B$31,3,2))),"")),IF($B7<>"ТТП",5,IF(O7="Да",5,4)),IFERROR(VLOOKUP(P7,Настройки!$A$35:$B$37,2,FALSE()),5),IFERROR(VLOOKUP(Q7,Настройки!$A$41:$B$44,2,FALSE()),5))) -> 4 | S7: =IF(R7="","",MIN(Настройки!$B$8,Настройки!$B$8*VLOOKUP(R7,Настройки!$A$16:$B$19,2,FALSE())+IF(AND($B7="ТТМ",O7="Да"),Настройки!$B$8*Настройки!$A$53,0))) -> 17.6 | T7: 6 | U7: Нет | V7: Частично | W7: 1 | X7: =IF(OR($A7="",T7=""),"",MIN(IF($B7="ТТП",IF(T7/Настройки!$C$9>=Настройки!$B$23,5,IF(T7/Настройки!$C$9>=Настройки!$B$24,4,IF(T7/Настройки!$C$9>=Настройки!$B$25,3,2))),IF($B7="ТТМ",IF(T7/Настройки!$C$9>=Настройки!$B$29,5,IF(T7/Настройки!$C$9>=Настройки!$B$30,4,IF(T7/Настройки!$C$9>=Настройки!$B$31,3,2))),"")),IF($B7<>"ТТП",5,IF(U7="Да",5,4)),IFERROR(VLOOKUP(V7,Настройки!$A$35:$B$37,2,FALSE()),5),IFERROR(VLOOKUP(W7,Настройки!$A$41:$B$44,2,FALSE()),5))) -> 4 | Y7: =IF(X7="","",MIN(Настройки!$B$9,Настройки!$B$9*VLOOKUP(X7,Настройки!$A$16:$B$19,2,FALSE())+IF(AND($B7="ТТМ",U7="Да"),Настройки!$B$9*Настройки!$A$53,0))) -> 17 | Z7: 4 | AA7: Нет | AB7: Уверенно | AC7: 0 | AD7: =IF(OR($A7="",Z7=""),"",MIN(IF($B7="ТТП",IF(Z7/Настройки!$C$10>=Настройки!$B$23,5,IF(Z7/Настройки!$C$10>=Настройки!$B$24,4,IF(Z7/Настройки!$C$10>=Настройки!$B$25,3,2))),IF($B7="ТТМ",IF(Z7/Настройки!$C$10>=Настройки!$B$29,5,IF(Z7/Настройки!$C$10>=Настройки!$B$30,4,IF(Z7/Настройки!$C$10>=Настройки!$B$31,3,2))),"")),IF($B7<>"ТТП",5,IF(AA7="Да",5,4)),IFERROR(VLOOKUP(AB7,Настройки!$A$35:$B$37,2,FALSE()),5),IFERROR(VLOOKUP(AC7,Настройки!$A$41:$B$44,2,FALSE()),5))) -> 3 | AE7: =IF(AD7="","",MIN(Настройки!$B$10,Настройки!$B$10*VLOOKUP(AD7,Настройки!$A$16:$B$19,2,FALSE())+IF(AND($B7="ТТМ",AA7="Да"),Настройки!$B$10*Настройки!$A$53,0))) -> 13 | AF7: 2 | AG7: Нет | AH7: Не может объяснить | AI7: 2 | AJ7: =IF(OR($A7="",AF7=""),"",MIN(IF($B7="ТТП",IF(AF7/Настройки!$C$11>=Настройки!$B$23,5,IF(AF7/Настройки!$C$11>=Настройки!$B$24,4,IF(AF7/Настройки!$C$11>=Настройки!$B$25,3,2))),IF($B7="ТТМ",IF(AF7/Настройки!$C$11>=Настройки!$B$29,5,IF(AF7/Настройки!$C$11>=Настройки!$B$30,4,IF(AF7/Настройки!$C$11>=Настройки!$B$31,3,2))),"")),IF($B7<>"ТТП",5,IF(AG7="Да",5,4)),IFERROR(VLOOKUP(AH7,Настройки!$A$35:$B$37,2,FALSE()),5),IFERROR(VLOOKUP(AI7,Настройки!$A$41:$B$44,2,FALSE()),5))) -> 2 | AK7: =IF(AJ7="","",MIN(Настройки!$B$11,Настройки!$B$11*VLOOKUP(AJ7,Настройки!$A$16:$B$19,2,FALSE())+IF(AND($B7="ТТМ",AG7="Да"),Настройки!$B$11*Настройки!$A$53,0))) -> 0 | AO7: =IF(OR($A7="",AL7=""),"",MIN(IF($B7="ТТП",IF(AL7/Настройки!$C$57>=Настройки!$B$23,5,IF(AL7/Настройки!$C$57>=Настройки!$B$24,4,IF(AL7/Настройки!$C$57>=Настройки!$B$25,3,2))),IF($B7="ТТМ",IF(AL7/Настройки!$C$57>=Настройки!$B$29,5,IF(AL7/Настройки!$C$57>=Настройки!$B$30,4,IF(AL7/Настройки!$C$57>=Настройки!$B$31,3,2))),"")),IF($B7<>"ТТП",5,IF(AM7="Да",5,4)),IFERROR(VLOOKUP(AN7,Настройки!$A$35:$B$37,2,FALSE()),5))) | AP7: =IF(AO7="","",MIN(Настройки!$B$57,Настройки!$B$57*VLOOKUP(AO7,Настройки!$A$16:$B$19,2,FALSE())+IF(AND($B7="ТТМ",AM7="Да"),Настройки!$B$57*Настройки!$A$53,0))) | AQ7: =IF($A7="","",SUM(G7,M7,S7,Y7,AE7,AK7)+IF(AP7="",0,AP7)) -> 70.35 | AR7: =IF(AQ7="","",VLOOKUP(AQ7,Настройки!$A$48:$B$51,2,TRUE())) -> 3
F8: =IF(OR($A8="",C8=""),"",MIN(IF($B8="ТТП",IF(C8/Настройки!$C$6>=Настройки!$B$23,5,IF(C8/Настройки!$C$6>=Настройки!$B$24,4,IF(C8/Настройки!$C$6>=Настройки!$B$25,3,2))),IF($B8="ТТМ",IF(C8/Настройки!$C$6>=Настройки!$B$29,5,IF(C8/Настройки!$C$6>=Настройки!$B$30,4,IF(C8/Настройки!$C$6>=Настройки!$B$31,3,2))),"")),IFERROR(VLOOKUP(D8,Настройки!$A$35:$B$37,2,FALSE()),5),IFERROR(VLOOKUP(E8,Настройки!$A$41:$B$44,2,FALSE()),5))) | G8: =IF(F8="","",Настройки!$B$6*VLOOKUP(F8,Настройки!$A$16:$B$19,2,FALSE())) | L8: =IF(OR($A8="",H8=""),"",MIN(IF($B8="ТТП",IF(H8/Настройки!$C$7>=Настройки!$B$23,5,IF(H8/Настройки!$C$7>=Настройки!$B$24,4,IF(H8/Настройки!$C$7>=Настройки!$B$25,3,2))),IF($B8="ТТМ",IF(H8/Настройки!$C$7>=Настройки!$B$29,5,IF(H8/Настройки!$C$7>=Настройки!$B$30,4,IF(H8/Настройки!$C$7>=Настройки!$B$31,3,2))),"")),IF($B8<>"ТТП",5,IF(I8="Да",5,4)),IFERROR(VLOOKUP(J8,Настройки!$A$35:$B$37,2,FALSE()),5),IFERROR(VLOOKUP(K8,Настройки!$A$41:$B$44,2,FALSE()),5))) | M8: =IF(L8="","",MIN(Настройки!$B$7,Настройки!$B$7*VLOOKUP(L8,Настройки!$A$16:$B$19,2,FALSE())+IF(AND($B8="ТТМ",I8="Да"),Настройки!$B$7*Настройки!$A$53,0))) | R8: =IF(OR($A8="",N8=""),"",MIN(IF($B8="ТТП",IF(N8/Настройки!$C$8>=Настройки!$B$23,5,IF(N8/Настройки!$C$8>=Настройки!$B$24,4,IF(N8/Настройки!$C$8>=Настройки!$B$25,3,2))),IF($B8="ТТМ",IF(N8/Настройки!$C$8>=Настройки!$B$29,5,IF(N8/Настройки!$C$8>=Настройки!$B$30,4,IF(N8/Настройки!$C$8>=Настройки!$B$31,3,2))),"")),IF($B8<>"ТТП",5,IF(O8="Да",5,4)),IFERROR(VLOOKUP(P8,Настройки!$A$35:$B$37,2,FALSE()),5),IFERROR(VLOOKUP(Q8,Настройки!$A$41:$B$44,2,FALSE()),5))) | S8: =IF(R8="","",MIN(Настройки!$B$8,Настройки!$B$8*VLOOKUP(R8,Настройки!$A$16:$B$19,2,FALSE())+IF(AND($B8="ТТМ",O8="Да"),Настройки!$B$8*Настройки!$A$53,0))) | X8: =IF(OR($A8="",T8=""),"",MIN(IF($B8="ТТП",IF(T8/Настройки!$C$9>=Настройки!$B$23,5,IF(T8/Настройки!$C$9>=Настройки!$B$24,4,IF(T8/Настройки!$C$9>=Настройки!$B$25,3,2))),IF($B8="ТТМ",IF(T8/Настройки!$C$9>=Настройки!$B$29,5,IF(T8/Настройки!$C$9>=Настройки!$B$30,4,IF(T8/Настройки!$C$9>=Настройки!$B$31,3,2))),"")),IF($B8<>"ТТП",5,IF(U8="Да",5,4)),IFERROR(VLOOKUP(V8,Настройки!$A$35:$B$37,2,FALSE()),5),IFERROR(VLOOKUP(W8,Настройки!$A$41:$B$44,2,FALSE()),5))) | Y8: =IF(X8="","",MIN(Настройки!$B$9,Настройки!$B$9*VLOOKUP(X8,Настройки!$A$16:$B$19,2,FALSE())+IF(AND($B8="ТТМ",U8="Да"),Настройки!$B$9*Настройки!$A$53,0))) | AD8: =IF(OR($A8="",Z8=""),"",MIN(IF($B8="ТТП",IF(Z8/Настройки!$C$10>=Настройки!$B$23,5,IF(Z8/Настройки!$C$10>=Настройки!$B$24,4,IF(Z8/Настройки!$C$10>=Настройки!$B$25,3,2))),IF($B8="ТТМ",IF(Z8/Настройки!$C$10>=Настройки!$B$29,5,IF(Z8/Настройки!$C$10>=Настройки!$B$30,4,IF(Z8/Настройки!$C$10>=Настройки!$B$31,3,2))),"")),IF($B8<>"ТТП",5,IF(AA8="Да",5,4)),IFERROR(VLOOKUP(AB8,Настройки!$A$35:$B$37,2,FALSE()),5),IFERROR(VLOOKUP(AC8,Настройки!$A$41:$B$44,2,FALSE()),5))) | AE8: =IF(AD8="","",MIN(Настройки!$B$10,Настройки!$B$10*VLOOKUP(AD8,Настройки!$A$16:$B$19,2,FALSE())+IF(AND($B8="ТТМ",AA8="Да"),Настройки!$B$10*Настройки!$A$53,0))) | AJ8: =IF(OR($A8="",AF8=""),"",MIN(IF($B8="ТТП",IF(AF8/Настройки!$C$11>=Настройки!$B$23,5,IF(AF8/Настройки!$C$11>=Настройки!$B$24,4,IF(AF8/Настройки!$C$11>=Настройки!$B$25,3,2))),IF($B8="ТТМ",IF(AF8/Настройки!$C$11>=Настройки!$B$29,5,IF(AF8/Настройки!$C$11>=Настройки!$B$30,4,IF(AF8/Настройки!$C$11>=Настройки!$B$31,3,2))),"")),IF($B8<>"ТТП",5,IF(AG8="Да",5,4)),IFERROR(VLOOKUP(AH8,Настройки!$A$35:$B$37,2,FALSE()),5),IFERROR(VLOOKUP(AI8,Настройки!$A$41:$B$44,2,FALSE()),5))) | AK8: =IF(AJ8="","",MIN(Настройки!$B$11,Настройки!$B$11*VLOOKUP(AJ8,Настройки!$A$16:$B$19,2,FALSE())+IF(AND($B8="ТТМ",AG8="Да"),Настройки!$B$11*Настройки!$A$53,0))) | AO8: =IF(OR($A8="",AL8=""),"",MIN(IF($B8="ТТП",IF(AL8/Настройки!$C$57>=Настройки!$B$23,5,IF(AL8/Настройки!$C$57>=Настройки!$B$24,4,IF(AL8/Настройки!$C$57>=Настройки!$B$25,3,2))),IF($B8="ТТМ",IF(AL8/Настройки!$C$57>=Настройки!$B$29,5,IF(AL8/Настройки!$C$57>=Настройки!$B$30,4,IF(AL8/Настройки!$C$57>=Настройки!$B$31,3,2))),"")),IF($B8<>"ТТП",5,IF(AM8="Да",5,4)),IFERROR(VLOOKUP(AN8,Настройки!$A$35:$B$37,2,FALSE()),5))) | AP8: =IF(AO8="","",MIN(Настройки!$B$57,Настройки!$B$57*VLOOKUP(AO8,Настройки!$A$16:$B$19,2,FALSE())+IF(AND($B8="ТТМ",AM8="Да"),Настройки!$B$57*Настройки!$A$53,0))) | AQ8: =IF($A8="","",SUM(G8,M8,S8,Y8,AE8,AK8)+IF(AP8="",0,AP8)) | AR8: =IF(AQ8="","",VLOOKUP(AQ8,Настройки!$A$48:$B$51,2,TRUE()))
F9: =IF(OR($A9="",C9=""),"",MIN(IF($B9="ТТП",IF(C9/Настройки!$C$6>=Настройки!$B$23,5,IF(C9/Настройки!$C$6>=Настройки!$B$24,4,IF(C9/Настройки!$C$6>=Настройки!$B$25,3,2))),IF($B9="ТТМ",IF(C9/Настройки!$C$6>=Настройки!$B$29,5,IF(C9/Настройки!$C$6>=Настройки!$B$30,4,IF(C9/Настройки!$C$6>=Настройки!$B$31,3,2))),"")),IFERROR(VLOOKUP(D9,Настройки!$A$35:$B$37,2,FALSE()),5),IFERROR(VLOOKUP(E9,Настройки!$A$41:$B$44,2,FALSE()),5))) | G9: =IF(F9="","",Настройки!$B$6*VLOOKUP(F9,Настройки!$A$16:$B$19,2,FALSE())) | L9: =IF(OR($A9="",H9=""),"",MIN(IF($B9="ТТП",IF(H9/Настройки!$C$7>=Настройки!$B$23,5,IF(H9/Настройки!$C$7>=Настройки!$B$24,4,IF(H9/Настройки!$C$7>=Настройки!$B$25,3,2))),IF($B9="ТТМ",IF(H9/Настройки!$C$7>=Настройки!$B$29,5,IF(H9/Настройки!$C$7>=Настройки!$B$30,4,IF(H9/Настройки!$C$7>=Настройки!$B$31,3,2))),"")),IF($B9<>"ТТП",5,IF(I9="Да",5,4)),IFERROR(VLOOKUP(J9,Настройки!$A$35:$B$37,2,FALSE()),5),IFERROR(VLOOKUP(K9,Настройки!$A$41:$B$44,2,FALSE()),5))) | M9: =IF(L9="","",MIN(Настройки!$B$7,Настройки!$B$7*VLOOKUP(L9,Настройки!$A$16:$B$19,2,FALSE())+IF(AND($B9="ТТМ",I9="Да"),Настройки!$B$7*Настройки!$A$53,0))) | R9: =IF(OR($A9="",N9=""),"",MIN(IF($B9="ТТП",IF(N9/Настройки!$C$8>=Настройки!$B$23,5,IF(N9/Настройки!$C$8>=Настройки!$B$24,4,IF(N9/Настройки!$C$8>=Настройки!$B$25,3,2))),IF($B9="ТТМ",IF(N9/Настройки!$C$8>=Настройки!$B$29,5,IF(N9/Настройки!$C$8>=Настройки!$B$30,4,IF(N9/Настройки!$C$8>=Настройки!$B$31,3,2))),"")),IF($B9<>"ТТП",5,IF(O9="Да",5,4)),IFERROR(VLOOKUP(P9,Настройки!$A$35:$B$37,2,FALSE()),5),IFERROR(VLOOKUP(Q9,Настройки!$A$41:$B$44,2,FALSE()),5))) | S9: =IF(R9="","",MIN(Настройки!$B$8,Настройки!$B$8*VLOOKUP(R9,Настройки!$A$16:$B$19,2,FALSE())+IF(AND($B9="ТТМ",O9="Да"),Настройки!$B$8*Настройки!$A$53,0))) | X9: =IF(OR($A9="",T9=""),"",MIN(IF($B9="ТТП",IF(T9/Настройки!$C$9>=Настройки!$B$23,5,IF(T9/Настройки!$C$9>=Настройки!$B$24,4,IF(T9/Настройки!$C$9>=Настройки!$B$25,3,2))),IF($B9="ТТМ",IF(T9/Настройки!$C$9>=Настройки!$B$29,5,IF(T9/Настройки!$C$9>=Настройки!$B$30,4,IF(T9/Настройки!$C$9>=Настройки!$B$31,3,2))),"")),IF($B9<>"ТТП",5,IF(U9="Да",5,4)),IFERROR(VLOOKUP(V9,Настройки!$A$35:$B$37,2,FALSE()),5),IFERROR(VLOOKUP(W9,Настройки!$A$41:$B$44,2,FALSE()),5))) | Y9: =IF(X9="","",MIN(Настройки!$B$9,Настройки!$B$9*VLOOKUP(X9,Настройки!$A$16:$B$19,2,FALSE())+IF(AND($B9="ТТМ",U9="Да"),Настройки!$B$9*Настройки!$A$53,0))) | AD9: =IF(OR($A9="",Z9=""),"",MIN(IF($B9="ТТП",IF(Z9/Настройки!$C$10>=Настройки!$B$23,5,IF(Z9/Настройки!$C$10>=Настройки!$B$24,4,IF(Z9/Настройки!$C$10>=Настройки!$B$25,3,2))),IF($B9="ТТМ",IF(Z9/Настройки!$C$10>=Настройки!$B$29,5,IF(Z9/Настройки!$C$10>=Настройки!$B$30,4,IF(Z9/Настройки!$C$10>=Настройки!$B$31,3,2))),"")),IF($B9<>"ТТП",5,IF(AA9="Да",5,4)),IFERROR(VLOOKUP(AB9,Настройки!$A$35:$B$37,2,FALSE()),5),IFERROR(VLOOKUP(AC9,Настройки!$A$41:$B$44,2,FALSE()),5))) | AE9: =IF(AD9="","",MIN(Настройки!$B$10,Настройки!$B$10*VLOOKUP(AD9,Настройки!$A$16:$B$19,2,FALSE())+IF(AND($B9="ТТМ",AA9="Да"),Настройки!$B$10*Настройки!$A$53,0))) | AJ9: =IF(OR($A9="",AF9=""),"",MIN(IF($B9="ТТП",IF(AF9/Настройки!$C$11>=Настройки!$B$23,5,IF(AF9/Настройки!$C$11>=Настройки!$B$24,4,IF(AF9/Настройки!$C$11>=Настройки!$B$25,3,2))),IF($B9="ТТМ",IF(AF9/Настройки!$C$11>=Настройки!$B$29,5,IF(AF9/Настройки!$C$11>=Настройки!$B$30,4,IF(AF9/Настройки!$C$11>=Настройки!$B$31,3,2))),"")),IF($B9<>"ТТП",5,IF(AG9="Да",5,4)),IFERROR(VLOOKUP(AH9,Настройки!$A$35:$B$37,2,FALSE()),5),IFERROR(VLOOKUP(AI9,Настройки!$A$41:$B$44,2,FALSE()),5))) | AK9: =IF(AJ9="","",MIN(Настройки!$B$11,Настройки!$B$11*VLOOKUP(AJ9,Настройки!$A$16:$B$19,2,FALSE())+IF(AND($B9="ТТМ",AG9="Да"),Настройки!$B$11*Настройки!$A$53,0))) | AO9: =IF(OR($A9="",AL9=""),"",MIN(IF($B9="ТТП",IF(AL9/Настройки!$C$57>=Настройки!$B$23,5,IF(AL9/Настройки!$C$57>=Настройки!$B$24,4,IF(AL9/Настройки!$C$57>=Настройки!$B$25,3,2))),IF($B9="ТТМ",IF(AL9/Настройки!$C$57>=Настройки!$B$29,5,IF(AL9/Настройки!$C$57>=Настройки!$B$30,4,IF(AL9/Настройки!$C$57>=Настройки!$B$31,3,2))),"")),IF($B9<>"ТТП",5,IF(AM9="Да",5,4)),IFERROR(VLOOKUP(AN9,Настройки!$A$35:$B$37,2,FALSE()),5))) | AP9: =IF(AO9="","",MIN(Настройки!$B$57,Настройки!$B$57*VLOOKUP(AO9,Настройки!$A$16:$B$19,2,FALSE())+IF(AND($B9="ТТМ",AM9="Да"),Настройки!$B$57*Настройки!$A$53,0))) | AQ9: =IF($A9="","",SUM(G9,M9,S9,Y9,AE9,AK9)+IF(AP9="",0,AP9)) | AR9: =IF(AQ9="","",VLOOKUP(AQ9,Настройки!$A$48:$B$51,2,TRUE()))
F10: =IF(OR($A10="",C10=""),"",MIN(IF($B10="ТТП",IF(C10/Настройки!$C$6>=Настройки!$B$23,5,IF(C10/Настройки!$C$6>=Настройки!$B$24,4,IF(C10/Настройки!$C$6>=Настройки!$B$25,3,2))),IF($B10="ТТМ",IF(C10/Настройки!$C$6>=Настройки!$B$29,5,IF(C10/Настройки!$C$6>=Настройки!$B$30,4,IF(C10/Настройки!$C$6>=Настройки!$B$31,3,2))),"")),IFERROR(VLOOKUP(D10,Настройки!$A$35:$B$37,2,FALSE()),5),IFERROR(VLOOKUP(E10,Настройки!$A$41:$B$44,2,FALSE()),5))) | G10: =IF(F10="","",Настройки!$B$6*VLOOKUP(F10,Настройки!$A$16:$B$19,2,FALSE())) | L10: =IF(OR($A10="",H10=""),"",MIN(IF($B10="ТТП",IF(H10/Настройки!$C$7>=Настройки!$B$23,5,IF(H10/Настройки!$C$7>=Настройки!$B$24,4,IF(H10/Настройки!$C$7>=Настройки!$B$25,3,2))),IF($B10="ТТМ",IF(H10/Настройки!$C$7>=Настройки!$B$29,5,IF(H10/Настройки!$C$7>=Настройки!$B$30,4,IF(H10/Настройки!$C$7>=Настройки!$B$31,3,2))),"")),IF($B10<>"ТТП",5,IF(I10="Да",5,4)),IFERROR(VLOOKUP(J10,Настройки!$A$35:$B$37,2,FALSE()),5),IFERROR(VLOOKUP(K10,Настройки!$A$41:$B$44,2,FALSE()),5))) | M10: =IF(L10="","",MIN(Настройки!$B$7,Настройки!$B$7*VLOOKUP(L10,Настройки!$A$16:$B$19,2,FALSE())+IF(AND($B10="ТТМ",I10="Да"),Настройки!$B$7*Настройки!$A$53,0))) | R10: =IF(OR($A10="",N10=""),"",MIN(IF($B10="ТТП",IF(N10/Настройки!$C$8>=Настройки!$B$23,5,IF(N10/Настройки!$C$8>=Настройки!$B$24,4,IF(N10/Настройки!$C$8>=Настройки!$B$25,3,2))),IF($B10="ТТМ",IF(N10/Настройки!$C$8>=Настройки!$B$29,5,IF(N10/Настройки!$C$8>=Настройки!$B$30,4,IF(N10/Настройки!$C$8>=Настройки!$B$31,3,2))),"")),IF($B10<>"ТТП",5,IF(O10="Да",5,4)),IFERROR(VLOOKUP(P10,Настройки!$A$35:$B$37,2,FALSE()),5),IFERROR(VLOOKUP(Q10,Настройки!$A$41:$B$44,2,FALSE()),5))) | S10: =IF(R10="","",MIN(Настройки!$B$8,Настройки!$B$8*VLOOKUP(R10,Настройки!$A$16:$B$19,2,FALSE())+IF(AND($B10="ТТМ",O10="Да"),Настройки!$B$8*Настройки!$A$53,0))) | X10: =IF(OR($A10="",T10=""),"",MIN(IF($B10="ТТП",IF(T10/Настройки!$C$9>=Настройки!$B$23,5,IF(T10/Настройки!$C$9>=Настройки!$B$24,4,IF(T10/Настройки!$C$9>=Настройки!$B$25,3,2))),IF($B10="ТТМ",IF(T10/Настройки!$C$9>=Настройки!$B$29,5,IF(T10/Настройки!$C$9>=Настройки!$B$30,4,IF(T10/Настройки!$C$9>=Настройки!$B$31,3,2))),"")),IF($B10<>"ТТП",5,IF(U10="Да",5,4)),IFERROR(VLOOKUP(V10,Настройки!$A$35:$B$37,2,FALSE()),5),IFERROR(VLOOKUP(W10,Настройки!$A$41:$B$44,2,FALSE()),5))) | Y10: =IF(X10="","",MIN(Настройки!$B$9,Настройки!$B$9*VLOOKUP(X10,Настройки!$A$16:$B$19,2,FALSE())+IF(AND($B10="ТТМ",U10="Да"),Настройки!$B$9*Настройки!$A$53,0))) | AD10: =IF(OR($A10="",Z10=""),"",MIN(IF($B10="ТТП",IF(Z10/Настройки!$C$10>=Настройки!$B$23,5,IF(Z10/Настройки!$C$10>=Настройки!$B$24,4,IF(Z10/Настройки!$C$10>=Настройки!$B$25,3,2))),IF($B10="ТТМ",IF(Z10/Настройки!$C$10>=Настройки!$B$29,5,IF(Z10/Настройки!$C$10>=Настройки!$B$30,4,IF(Z10/Настройки!$C$10>=Настройки!$B$31,3,2))),"")),IF($B10<>"ТТП",5,IF(AA10="Да",5,4)),IFERROR(VLOOKUP(AB10,Настройки!$A$35:$B$37,2,FALSE()),5),IFERROR(VLOOKUP(AC10,Настройки!$A$41:$B$44,2,FALSE()),5))) | AE10: =IF(AD10="","",MIN(Настройки!$B$10,Настройки!$B$10*VLOOKUP(AD10,Настройки!$A$16:$B$19,2,FALSE())+IF(AND($B10="ТТМ",AA10="Да"),Настройки!$B$10*Настройки!$A$53,0))) | AJ10: =IF(OR($A10="",AF10=""),"",MIN(IF($B10="ТТП",IF(AF10/Настройки!$C$11>=Настройки!$B$23,5,IF(AF10/Настройки!$C$11>=Настройки!$B$24,4,IF(AF10/Настройки!$C$11>=Настройки!$B$25,3,2))),IF($B10="ТТМ",IF(AF10/Настройки!$C$11>=Настройки!$B$29,5,IF(AF10/Настройки!$C$11>=Настройки!$B$30,4,IF(AF10/Настройки!$C$11>=Настройки!$B$31,3,2))),"")),IF($B10<>"ТТП",5,IF(AG10="Да",5,4)),IFERROR(VLOOKUP(AH10,Настройки!$A$35:$B$37,2,FALSE()),5),IFERROR(VLOOKUP(AI10,Настройки!$A$41:$B$44,2,FALSE()),5))) | AK10: =IF(AJ10="","",MIN(Настройки!$B$11,Настройки!$B$11*VLOOKUP(AJ10,Настройки!$A$16:$B$19,2,FALSE())+IF(AND($B10="ТТМ",AG10="Да"),Настройки!$B$11*Настройки!$A$53,0))) | AO10: =IF(OR($A10="",AL10=""),"",MIN(IF($B10="ТТП",IF(AL10/Настройки!$C$57>=Настройки!$B$23,5,IF(AL10/Настройки!$C$57>=Настройки!$B$24,4,IF(AL10/Настройки!$C$57>=Настройки!$B$25,3,2))),IF($B10="ТТМ",IF(AL10/Настройки!$C$57>=Настройки!$B$29,5,IF(AL10/Настройки!$C$57>=Настройки!$B$30,4,IF(AL10/Настройки!$C$57>=Настройки!$B$31,3,2))),"")),IF($B10<>"ТТП",5,IF(AM10="Да",5,4)),IFERROR(VLOOKUP(AN10,Настройки!$A$35:$B$37,2,FALSE()),5))) | AP10: =IF(AO10="","",MIN(Настройки!$B$57,Настройки!$B$57*VLOOKUP(AO10,Настройки!$A$16:$B$19,2,FALSE())+IF(AND($B10="ТТМ",AM10="Да"),Настройки!$B$57*Настройки!$A$53,0))) | AQ10: =IF($A10="","",SUM(G10,M10,S10,Y10,AE10,AK10)+IF(AP10="",0,AP10)) | AR10: =IF(AQ10="","",VLOOKUP(AQ10,Настройки!$A$48:$B$51,2,TRUE()))
F11: =IF(OR($A11="",C11=""),"",MIN(IF($B11="ТТП",IF(C11/Настройки!$C$6>=Настройки!$B$23,5,IF(C11/Настройки!$C$6>=Настройки!$B$24,4,IF(C11/Настройки!$C$6>=Настройки!$B$25,3,2))),IF($B11="ТТМ",IF(C11/Настройки!$C$6>=Настройки!$B$29,5,IF(C11/Настройки!$C$6>=Настройки!$B$30,4,IF(C11/Настройки!$C$6>=Настройки!$B$31,3,2))),"")),IFERROR(VLOOKUP(D11,Настройки!$A$35:$B$37,2,FALSE()),5),IFERROR(VLOOKUP(E11,Настройки!$A$41:$B$44,2,FALSE()),5))) | G11: =IF(F11="","",Настройки!$B$6*VLOOKUP(F11,Настройки!$A$16:$B$19,2,FALSE())) | L11: =IF(OR($A11="",H11=""),"",MIN(IF($B11="ТТП",IF(H11/Настройки!$C$7>=Настройки!$B$23,5,IF(H11/Настройки!$C$7>=Настройки!$B$24,4,IF(H11/Настройки!$C$7>=Настройки!$B$25,3,2))),IF($B11="ТТМ",IF(H11/Настройки!$C$7>=Настройки!$B$29,5,IF(H11/Настройки!$C$7>=Настройки!$B$30,4,IF(H11/Настройки!$C$7>=Настройки!$B$31,3,2))),"")),IF($B11<>"ТТП",5,IF(I11="Да",5,4)),IFERROR(VLOOKUP(J11,Настройки!$A$35:$B$37,2,FALSE()),5),IFERROR(VLOOKUP(K11,Настройки!$A$41:$B$44,2,FALSE()),5))) | M11: =IF(L11="","",MIN(Настройки!$B$7,Настройки!$B$7*VLOOKUP(L11,Настройки!$A$16:$B$19,2,FALSE())+IF(AND($B11="ТТМ",I11="Да"),Настройки!$B$7*Настройки!$A$53,0))) | R11: =IF(OR($A11="",N11=""),"",MIN(IF($B11="ТТП",IF(N11/Настройки!$C$8>=Настройки!$B$23,5,IF(N11/Настройки!$C$8>=Настройки!$B$24,4,IF(N11/Настройки!$C$8>=Настройки!$B$25,3,2))),IF($B11="ТТМ",IF(N11/Настройки!$C$8>=Настройки!$B$29,5,IF(N11/Настройки!$C$8>=Настройки!$B$30,4,IF(N11/Настройки!$C$8>=Настройки!$B$31,3,2))),"")),IF($B11<>"ТТП",5,IF(O11="Да",5,4)),IFERROR(VLOOKUP(P11,Настройки!$A$35:$B$37,2,FALSE()),5),IFERROR(VLOOKUP(Q11,Настройки!$A$41:$B$44,2,FALSE()),5))) | S11: =IF(R11="","",MIN(Настройки!$B$8,Настройки!$B$8*VLOOKUP(R11,Настройки!$A$16:$B$19,2,FALSE())+IF(AND($B11="ТТМ",O11="Да"),Настройки!$B$8*Настройки!$A$53,0))) | X11: =IF(OR($A11="",T11=""),"",MIN(IF($B11="ТТП",IF(T11/Настройки!$C$9>=Настройки!$B$23,5,IF(T11/Настройки!$C$9>=Настройки!$B$24,4,IF(T11/Настройки!$C$9>=Настройки!$B$25,3,2))),IF($B11="ТТМ",IF(T11/Настройки!$C$9>=Настройки!$B$29,5,IF(T11/Настройки!$C$9>=Настройки!$B$30,4,IF(T11/Настройки!$C$9>=Настройки!$B$31,3,2))),"")),IF($B11<>"ТТП",5,IF(U11="Да",5,4)),IFERROR(VLOOKUP(V11,Настройки!$A$35:$B$37,2,FALSE()),5),IFERROR(VLOOKUP(W11,Настройки!$A$41:$B$44,2,FALSE()),5))) | Y11: =IF(X11="","",MIN(Настройки!$B$9,Настройки!$B$9*VLOOKUP(X11,Настройки!$A$16:$B$19,2,FALSE())+IF(AND($B11="ТТМ",U11="Да"),Настройки!$B$9*Настройки!$A$53,0))) | AD11: =IF(OR($A11="",Z11=""),"",MIN(IF($B11="ТТП",IF(Z11/Настройки!$C$10>=Настройки!$B$23,5,IF(Z11/Настройки!$C$10>=Настройки!$B$24,4,IF(Z11/Настройки!$C$10>=Настройки!$B$25,3,2))),IF($B11="ТТМ",IF(Z11/Настройки!$C$10>=Настройки!$B$29,5,IF(Z11/Настройки!$C$10>=Настройки!$B$30,4,IF(Z11/Настройки!$C$10>=Настройки!$B$31,3,2))),"")),IF($B11<>"ТТП",5,IF(AA11="Да",5,4)),IFERROR(VLOOKUP(AB11,Настройки!$A$35:$B$37,2,FALSE()),5),IFERROR(VLOOKUP(AC11,Настройки!$A$41:$B$44,2,FALSE()),5))) | AE11: =IF(AD11="","",MIN(Настройки!$B$10,Настройки!$B$10*VLOOKUP(AD11,Настройки!$A$16:$B$19,2,FALSE())+IF(AND($B11="ТТМ",AA11="Да"),Настройки!$B$10*Настройки!$A$53,0))) | AJ11: =IF(OR($A11="",AF11=""),"",MIN(IF($B11="ТТП",IF(AF11/Настройки!$C$11>=Настройки!$B$23,5,IF(AF11/Настройки!$C$11>=Настройки!$B$24,4,IF(AF11/Настройки!$C$11>=Настройки!$B$25,3,2))),IF($B11="ТТМ",IF(AF11/Настройки!$C$11>=Настройки!$B$29,5,IF(AF11/Настройки!$C$11>=Настройки!$B$30,4,IF(AF11/Настройки!$C$11>=Настройки!$B$31,3,2))),"")),IF($B11<>"ТТП",5,IF(AG11="Да",5,4)),IFERROR(VLOOKUP(AH11,Настройки!$A$35:$B$37,2,FALSE()),5),IFERROR(VLOOKUP(AI11,Настройки!$A$41:$B$44,2,FALSE()),5))) | AK11: =IF(AJ11="","",MIN(Настройки!$B$11,Настройки!$B$11*VLOOKUP(AJ11,Настройки!$A$16:$B$19,2,FALSE())+IF(AND($B11="ТТМ",AG11="Да"),Настройки!$B$11*Настройки!$A$53,0))) | AO11: =IF(OR($A11="",AL11=""),"",MIN(IF($B11="ТТП",IF(AL11/Настройки!$C$57>=Настройки!$B$23,5,IF(AL11/Настройки!$C$57>=Настройки!$B$24,4,IF(AL11/Настройки!$C$57>=Настройки!$B$25,3,2))),IF($B11="ТТМ",IF(AL11/Настройки!$C$57>=Настройки!$B$29,5,IF(AL11/Настройки!$C$57>=Настройки!$B$30,4,IF(AL11/Настройки!$C$57>=Настройки!$B$31,3,2))),"")),IF($B11<>"ТТП",5,IF(AM11="Да",5,4)),IFERROR(VLOOKUP(AN11,Настройки!$A$35:$B$37,2,FALSE()),5))) | AP11: =IF(AO11="","",MIN(Настройки!$B$57,Настройки!$B$57*VLOOKUP(AO11,Настройки!$A$16:$B$19,2,FALSE())+IF(AND($B11="ТТМ",AM11="Да"),Настройки!$B$57*Настройки!$A$53,0))) | AQ11: =IF($A11="","",SUM(G11,M11,S11,Y11,AE11,AK11)+IF(AP11="",0,AP11)) | AR11: =IF(AQ11="","",VLOOKUP(AQ11,Настройки!$A$48:$B$51,2,TRUE()))
F12: =IF(OR($A12="",C12=""),"",MIN(IF($B12="ТТП",IF(C12/Настройки!$C$6>=Настройки!$B$23,5,IF(C12/Настройки!$C$6>=Настройки!$B$24,4,IF(C12/Настройки!$C$6>=Настройки!$B$25,3,2))),IF($B12="ТТМ",IF(C12/Настройки!$C$6>=Настройки!$B$29,5,IF(C12/Настройки!$C$6>=Настройки!$B$30,4,IF(C12/Настройки!$C$6>=Настройки!$B$31,3,2))),"")),IFERROR(VLOOKUP(D12,Настройки!$A$35:$B$37,2,FALSE()),5),IFERROR(VLOOKUP(E12,Настройки!$A$41:$B$44,2,FALSE()),5))) | G12: =IF(F12="","",Настройки!$B$6*VLOOKUP(F12,Настройки!$A$16:$B$19,2,FALSE())) | L12: =IF(OR($A12="",H12=""),"",MIN(IF($B12="ТТП",IF(H12/Настройки!$C$7>=Настройки!$B$23,5,IF(H12/Настройки!$C$7>=Настройки!$B$24,4,IF(H12/Настройки!$C$7>=Настройки!$B$25,3,2))),IF($B12="ТТМ",IF(H12/Настройки!$C$7>=Настройки!$B$29,5,IF(H12/Настройки!$C$7>=Настройки!$B$30,4,IF(H12/Настройки!$C$7>=Настройки!$B$31,3,2))),"")),IF($B12<>"ТТП",5,IF(I12="Да",5,4)),IFERROR(VLOOKUP(J12,Настройки!$A$35:$B$37,2,FALSE()),5),IFERROR(VLOOKUP(K12,Настройки!$A$41:$B$44,2,FALSE()),5))) | M12: =IF(L12="","",MIN(Настройки!$B$7,Настройки!$B$7*VLOOKUP(L12,Настройки!$A$16:$B$19,2,FALSE())+IF(AND($B12="ТТМ",I12="Да"),Настройки!$B$7*Настройки!$A$53,0))) | R12: =IF(OR($A12="",N12=""),"",MIN(IF($B12="ТТП",IF(N12/Настройки!$C$8>=Настройки!$B$23,5,IF(N12/Настройки!$C$8>=Настройки!$B$24,4,IF(N12/Настройки!$C$8>=Настройки!$B$25,3,2))),IF($B12="ТТМ",IF(N12/Настройки!$C$8>=Настройки!$B$29,5,IF(N12/Настройки!$C$8>=Настройки!$B$30,4,IF(N12/Настройки!$C$8>=Настройки!$B$31,3,2))),"")),IF($B12<>"ТТП",5,IF(O12="Да",5,4)),IFERROR(VLOOKUP(P12,Настройки!$A$35:$B$37,2,FALSE()),5),IFERROR(VLOOKUP(Q12,Настройки!$A$41:$B$44,2,FALSE()),5))) | S12: =IF(R12="","",MIN(Настройки!$B$8,Настройки!$B$8*VLOOKUP(R12,Настройки!$A$16:$B$19,2,FALSE())+IF(AND($B12="ТТМ",O12="Да"),Настройки!$B$8*Настройки!$A$53,0))) | X12: =IF(OR($A12="",T12=""),"",MIN(IF($B12="ТТП",IF(T12/Настройки!$C$9>=Настройки!$B$23,5,IF(T12/Настройки!$C$9>=Настройки!$B$24,4,IF(T12/Настройки!$C$9>=Настройки!$B$25,3,2))),IF($B12="ТТМ",IF(T12/Настройки!$C$9>=Настройки!$B$29,5,IF(T12/Настройки!$C$9>=Настройки!$B$30,4,IF(T12/Настройки!$C$9>=Настройки!$B$31,3,2))),"")),IF($B12<>"ТТП",5,IF(U12="Да",5,4)),IFERROR(VLOOKUP(V12,Настройки!$A$35:$B$37,2,FALSE()),5),IFERROR(VLOOKUP(W12,Настройки!$A$41:$B$44,2,FALSE()),5))) | Y12: =IF(X12="","",MIN(Настройки!$B$9,Настройки!$B$9*VLOOKUP(X12,Настройки!$A$16:$B$19,2,FALSE())+IF(AND($B12="ТТМ",U12="Да"),Настройки!$B$9*Настройки!$A$53,0))) | AD12: =IF(OR($A12="",Z12=""),"",MIN(IF($B12="ТТП",IF(Z12/Настройки!$C$10>=Настройки!$B$23,5,IF(Z12/Настройки!$C$10>=Настройки!$B$24,4,IF(Z12/Настройки!$C$10>=Настройки!$B$25,3,2))),IF($B12="ТТМ",IF(Z12/Настройки!$C$10>=Настройки!$B$29,5,IF(Z12/Настройки!$C$10>=Настройки!$B$30,4,IF(Z12/Настройки!$C$10>=Настройки!$B$31,3,2))),"")),IF($B12<>"ТТП",5,IF(AA12="Да",5,4)),IFERROR(VLOOKUP(AB12,Настройки!$A$35:$B$37,2,FALSE()),5),IFERROR(VLOOKUP(AC12,Настройки!$A$41:$B$44,2,FALSE()),5))) | AE12: =IF(AD12="","",MIN(Настройки!$B$10,Настройки!$B$10*VLOOKUP(AD12,Настройки!$A$16:$B$19,2,FALSE())+IF(AND($B12="ТТМ",AA12="Да"),Настройки!$B$10*Настройки!$A$53,0))) | AJ12: =IF(OR($A12="",AF12=""),"",MIN(IF($B12="ТТП",IF(AF12/Настройки!$C$11>=Настройки!$B$23,5,IF(AF12/Настройки!$C$11>=Настройки!$B$24,4,IF(AF12/Настройки!$C$11>=Настройки!$B$25,3,2))),IF($B12="ТТМ",IF(AF12/Настройки!$C$11>=Настройки!$B$29,5,IF(AF12/Настройки!$C$11>=Настройки!$B$30,4,IF(AF12/Настройки!$C$11>=Настройки!$B$31,3,2))),"")),IF($B12<>"ТТП",5,IF(AG12="Да",5,4)),IFERROR(VLOOKUP(AH12,Настройки!$A$35:$B$37,2,FALSE()),5),IFERROR(VLOOKUP(AI12,Настройки!$A$41:$B$44,2,FALSE()),5))) | AK12: =IF(AJ12="","",MIN(Настройки!$B$11,Настройки!$B$11*VLOOKUP(AJ12,Настройки!$A$16:$B$19,2,FALSE())+IF(AND($B12="ТТМ",AG12="Да"),Настройки!$B$11*Настройки!$A$53,0))) | AO12: =IF(OR($A12="",AL12=""),"",MIN(IF($B12="ТТП",IF(AL12/Настройки!$C$57>=Настройки!$B$23,5,IF(AL12/Настройки!$C$57>=Настройки!$B$24,4,IF(AL12/Настройки!$C$57>=Настройки!$B$25,3,2))),IF($B12="ТТМ",IF(AL12/Настройки!$C$57>=Настройки!$B$29,5,IF(AL12/Настройки!$C$57>=Настройки!$B$30,4,IF(AL12/Настройки!$C$57>=Настройки!$B$31,3,2))),"")),IF($B12<>"ТТП",5,IF(AM12="Да",5,4)),IFERROR(VLOOKUP(AN12,Настройки!$A$35:$B$37,2,FALSE()),5))) | AP12: =IF(AO12="","",MIN(Настройки!$B$57,Настройки!$B$57*VLOOKUP(AO12,Настройки!$A$16:$B$19,2,FALSE())+IF(AND($B12="ТТМ",AM12="Да"),Настройки!$B$57*Настройки!$A$53,0))) | AQ12: =IF($A12="","",SUM(G12,M12,S12,Y12,AE12,AK12)+IF(AP12="",0,AP12)) | AR12: =IF(AQ12="","",VLOOKUP(AQ12,Настройки!$A$48:$B$51,2,TRUE()))
F13: =IF(OR($A13="",C13=""),"",MIN(IF($B13="ТТП",IF(C13/Настройки!$C$6>=Настройки!$B$23,5,IF(C13/Настройки!$C$6>=Настройки!$B$24,4,IF(C13/Настройки!$C$6>=Настройки!$B$25,3,2))),IF($B13="ТТМ",IF(C13/Настройки!$C$6>=Настройки!$B$29,5,IF(C13/Настройки!$C$6>=Настройки!$B$30,4,IF(C13/Настройки!$C$6>=Настройки!$B$31,3,2))),"")),IFERROR(VLOOKUP(D13,Настройки!$A$35:$B$37,2,FALSE()),5),IFERROR(VLOOKUP(E13,Настройки!$A$41:$B$44,2,FALSE()),5))) | G13: =IF(F13="","",Настройки!$B$6*VLOOKUP(F13,Настройки!$A$16:$B$19,2,FALSE())) | L13: =IF(OR($A13="",H13=""),"",MIN(IF($B13="ТТП",IF(H13/Настройки!$C$7>=Настройки!$B$23,5,IF(H13/Настройки!$C$7>=Настройки!$B$24,4,IF(H13/Настройки!$C$7>=Настройки!$B$25,3,2))),IF($B13="ТТМ",IF(H13/Настройки!$C$7>=Настройки!$B$29,5,IF(H13/Настройки!$C$7>=Настройки!$B$30,4,IF(H13/Настройки!$C$7>=Настройки!$B$31,3,2))),"")),IF($B13<>"ТТП",5,IF(I13="Да",5,4)),IFERROR(VLOOKUP(J13,Настройки!$A$35:$B$37,2,FALSE()),5),IFERROR(VLOOKUP(K13,Настройки!$A$41:$B$44,2,FALSE()),5))) | M13: =IF(L13="","",MIN(Настройки!$B$7,Настройки!$B$7*VLOOKUP(L13,Настройки!$A$16:$B$19,2,FALSE())+IF(AND($B13="ТТМ",I13="Да"),Настройки!$B$7*Настройки!$A$53,0))) | R13: =IF(OR($A13="",N13=""),"",MIN(IF($B13="ТТП",IF(N13/Настройки!$C$8>=Настройки!$B$23,5,IF(N13/Настройки!$C$8>=Настройки!$B$24,4,IF(N13/Настройки!$C$8>=Настройки!$B$25,3,2))),IF($B13="ТТМ",IF(N13/Настройки!$C$8>=Настройки!$B$29,5,IF(N13/Настройки!$C$8>=Настройки!$B$30,4,IF(N13/Настройки!$C$8>=Настройки!$B$31,3,2))),"")),IF($B13<>"ТТП",5,IF(O13="Да",5,4)),IFERROR(VLOOKUP(P13,Настройки!$A$35:$B$37,2,FALSE()),5),IFERROR(VLOOKUP(Q13,Настройки!$A$41:$B$44,2,FALSE()),5))) | S13: =IF(R13="","",MIN(Настройки!$B$8,Настройки!$B$8*VLOOKUP(R13,Настройки!$A$16:$B$19,2,FALSE())+IF(AND($B13="ТТМ",O13="Да"),Настройки!$B$8*Настройки!$A$53,0))) | X13: =IF(OR($A13="",T13=""),"",MIN(IF($B13="ТТП",IF(T13/Настройки!$C$9>=Настройки!$B$23,5,IF(T13/Настройки!$C$9>=Настройки!$B$24,4,IF(T13/Настройки!$C$9>=Настройки!$B$25,3,2))),IF($B13="ТТМ",IF(T13/Настройки!$C$9>=Настройки!$B$29,5,IF(T13/Настройки!$C$9>=Настройки!$B$30,4,IF(T13/Настройки!$C$9>=Настройки!$B$31,3,2))),"")),IF($B13<>"ТТП",5,IF(U13="Да",5,4)),IFERROR(VLOOKUP(V13,Настройки!$A$35:$B$37,2,FALSE()),5),IFERROR(VLOOKUP(W13,Настройки!$A$41:$B$44,2,FALSE()),5))) | Y13: =IF(X13="","",MIN(Настройки!$B$9,Настройки!$B$9*VLOOKUP(X13,Настройки!$A$16:$B$19,2,FALSE())+IF(AND($B13="ТТМ",U13="Да"),Настройки!$B$9*Настройки!$A$53,0))) | AD13: =IF(OR($A13="",Z13=""),"",MIN(IF($B13="ТТП",IF(Z13/Настройки!$C$10>=Настройки!$B$23,5,IF(Z13/Настройки!$C$10>=Настройки!$B$24,4,IF(Z13/Настройки!$C$10>=Настройки!$B$25,3,2))),IF($B13="ТТМ",IF(Z13/Настройки!$C$10>=Настройки!$B$29,5,IF(Z13/Настройки!$C$10>=Настройки!$B$30,4,IF(Z13/Настройки!$C$10>=Настройки!$B$31,3,2))),"")),IF($B13<>"ТТП",5,IF(AA13="Да",5,4)),IFERROR(VLOOKUP(AB13,Настройки!$A$35:$B$37,2,FALSE()),5),IFERROR(VLOOKUP(AC13,Настройки!$A$41:$B$44,2,FALSE()),5))) | AE13: =IF(AD13="","",MIN(Настройки!$B$10,Настройки!$B$10*VLOOKUP(AD13,Настройки!$A$16:$B$19,2,FALSE())+IF(AND($B13="ТТМ",AA13="Да"),Настройки!$B$10*Настройки!$A$53,0))) | AJ13: =IF(OR($A13="",AF13=""),"",MIN(IF($B13="ТТП",IF(AF13/Настройки!$C$11>=Настройки!$B$23,5,IF(AF13/Настройки!$C$11>=Настройки!$B$24,4,IF(AF13/Настройки!$C$11>=Настройки!$B$25,3,2))),IF($B13="ТТМ",IF(AF13/Настройки!$C$11>=Настройки!$B$29,5,IF(AF13/Настройки!$C$11>=Настройки!$B$30,4,IF(AF13/Настройки!$C$11>=Настройки!$B$31,3,2))),"")),IF($B13<>"ТТП",5,IF(AG13="Да",5,4)),IFERROR(VLOOKUP(AH13,Настройки!$A$35:$B$37,2,FALSE()),5),IFERROR(VLOOKUP(AI13,Настройки!$A$41:$B$44,2,FALSE()),5))) | AK13: =IF(AJ13="","",MIN(Настройки!$B$11,Настройки!$B$11*VLOOKUP(AJ13,Настройки!$A$16:$B$19,2,FALSE())+IF(AND($B13="ТТМ",AG13="Да"),Настройки!$B$11*Настройки!$A$53,0))) | AO13: =IF(OR($A13="",AL13=""),"",MIN(IF($B13="ТТП",IF(AL13/Настройки!$C$57>=Настройки!$B$23,5,IF(AL13/Настройки!$C$57>=Настройки!$B$24,4,IF(AL13/Настройки!$C$57>=Настройки!$B$25,3,2))),IF($B13="ТТМ",IF(AL13/Настройки!$C$57>=Настройки!$B$29,5,IF(AL13/Настройки!$C$57>=Настройки!$B$30,4,IF(AL13/Настройки!$C$57>=Настройки!$B$31,3,2))),"")),IF($B13<>"ТТП",5,IF(AM13="Да",5,4)),IFERROR(VLOOKUP(AN13,Настройки!$A$35:$B$37,2,FALSE()),5))) | AP13: =IF(AO13="","",MIN(Настройки!$B$57,Настройки!$B$57*VLOOKUP(AO13,Настройки!$A$16:$B$19,2,FALSE())+IF(AND($B13="ТТМ",AM13="Да"),Настройки!$B$57*Настройки!$A$53,0))) | AQ13: =IF($A13="","",SUM(G13,M13,S13,Y13,AE13,AK13)+IF(AP13="",0,AP13)) | AR13: =IF(AQ13="","",VLOOKUP(AQ13,Настройки!$A$48:$B$51,2,TRUE()))
F14: =IF(OR($A14="",C14=""),"",MIN(IF($B14="ТТП",IF(C14/Настройки!$C$6>=Настройки!$B$23,5,IF(C14/Настройки!$C$6>=Настройки!$B$24,4,IF(C14/Настройки!$C$6>=Настройки!$B$25,3,2))),IF($B14="ТТМ",IF(C14/Настройки!$C$6>=Настройки!$B$29,5,IF(C14/Настройки!$C$6>=Настройки!$B$30,4,IF(C14/Настройки!$C$6>=Настройки!$B$31,3,2))),"")),IFERROR(VLOOKUP(D14,Настройки!$A$35:$B$37,2,FALSE()),5),IFERROR(VLOOKUP(E14,Настройки!$A$41:$B$44,2,FALSE()),5))) | G14: =IF(F14="","",Настройки!$B$6*VLOOKUP(F14,Настройки!$A$16:$B$19,2,FALSE())) | L14: =IF(OR($A14="",H14=""),"",MIN(IF($B14="ТТП",IF(H14/Настройки!$C$7>=Настройки!$B$23,5,IF(H14/Настройки!$C$7>=Настройки!$B$24,4,IF(H14/Настройки!$C$7>=Настройки!$B$25,3,2))),IF($B14="ТТМ",IF(H14/Настройки!$C$7>=Настройки!$B$29,5,IF(H14/Настройки!$C$7>=Настройки!$B$30,4,IF(H14/Настройки!$C$7>=Настройки!$B$31,3,2))),"")),IF($B14<>"ТТП",5,IF(I14="Да",5,4)),IFERROR(VLOOKUP(J14,Настройки!$A$35:$B$37,2,FALSE()),5),IFERROR(VLOOKUP(K14,Настройки!$A$41:$B$44,2,FALSE()),5))) | M14: =IF(L14="","",MIN(Настройки!$B$7,Настройки!$B$7*VLOOKUP(L14,Настройки!$A$16:$B$19,2,FALSE())+IF(AND($B14="ТТМ",I14="Да"),Настройки!$B$7*Настройки!$A$53,0))) | R14: =IF(OR($A14="",N14=""),"",MIN(IF($B14="ТТП",IF(N14/Настройки!$C$8>=Настройки!$B$23,5,IF(N14/Настройки!$C$8>=Настройки!$B$24,4,IF(N14/Настройки!$C$8>=Настройки!$B$25,3,2))),IF($B14="ТТМ",IF(N14/Настройки!$C$8>=Настройки!$B$29,5,IF(N14/Настройки!$C$8>=Настройки!$B$30,4,IF(N14/Настройки!$C$8>=Настройки!$B$31,3,2))),"")),IF($B14<>"ТТП",5,IF(O14="Да",5,4)),IFERROR(VLOOKUP(P14,Настройки!$A$35:$B$37,2,FALSE()),5),IFERROR(VLOOKUP(Q14,Настройки!$A$41:$B$44,2,FALSE()),5))) | S14: =IF(R14="","",MIN(Настройки!$B$8,Настройки!$B$8*VLOOKUP(R14,Настройки!$A$16:$B$19,2,FALSE())+IF(AND($B14="ТТМ",O14="Да"),Настройки!$B$8*Настройки!$A$53,0))) | X14: =IF(OR($A14="",T14=""),"",MIN(IF($B14="ТТП",IF(T14/Настройки!$C$9>=Настройки!$B$23,5,IF(T14/Настройки!$C$9>=Настройки!$B$24,4,IF(T14/Настройки!$C$9>=Настройки!$B$25,3,2))),IF($B14="ТТМ",IF(T14/Настройки!$C$9>=Настройки!$B$29,5,IF(T14/Настройки!$C$9>=Настройки!$B$30,4,IF(T14/Настройки!$C$9>=Настройки!$B$31,3,2))),"")),IF($B14<>"ТТП",5,IF(U14="Да",5,4)),IFERROR(VLOOKUP(V14,Настройки!$A$35:$B$37,2,FALSE()),5),IFERROR(VLOOKUP(W14,Настройки!$A$41:$B$44,2,FALSE()),5))) | Y14: =IF(X14="","",MIN(Настройки!$B$9,Настройки!$B$9*VLOOKUP(X14,Настройки!$A$16:$B$19,2,FALSE())+IF(AND($B14="ТТМ",U14="Да"),Настройки!$B$9*Настройки!$A$53,0))) | AD14: =IF(OR($A14="",Z14=""),"",MIN(IF($B14="ТТП",IF(Z14/Настройки!$C$10>=Настройки!$B$23,5,IF(Z14/Настройки!$C$10>=Настройки!$B$24,4,IF(Z14/Настройки!$C$10>=Настройки!$B$25,3,2))),IF($B14="ТТМ",IF(Z14/Настройки!$C$10>=Настройки!$B$29,5,IF(Z14/Настройки!$C$10>=Настройки!$B$30,4,IF(Z14/Настройки!$C$10>=Настройки!$B$31,3,2))),"")),IF($B14<>"ТТП",5,IF(AA14="Да",5,4)),IFERROR(VLOOKUP(AB14,Настройки!$A$35:$B$37,2,FALSE()),5),IFERROR(VLOOKUP(AC14,Настройки!$A$41:$B$44,2,FALSE()),5))) | AE14: =IF(AD14="","",MIN(Настройки!$B$10,Настройки!$B$10*VLOOKUP(AD14,Настройки!$A$16:$B$19,2,FALSE())+IF(AND($B14="ТТМ",AA14="Да"),Настройки!$B$10*Настройки!$A$53,0))) | AJ14: =IF(OR($A14="",AF14=""),"",MIN(IF($B14="ТТП",IF(AF14/Настройки!$C$11>=Настройки!$B$23,5,IF(AF14/Настройки!$C$11>=Настройки!$B$24,4,IF(AF14/Настройки!$C$11>=Настройки!$B$25,3,2))),IF($B14="ТТМ",IF(AF14/Настройки!$C$11>=Настройки!$B$29,5,IF(AF14/Настройки!$C$11>=Настройки!$B$30,4,IF(AF14/Настройки!$C$11>=Настройки!$B$31,3,2))),"")),IF($B14<>"ТТП",5,IF(AG14="Да",5,4)),IFERROR(VLOOKUP(AH14,Настройки!$A$35:$B$37,2,FALSE()),5),IFERROR(VLOOKUP(AI14,Настройки!$A$41:$B$44,2,FALSE()),5))) | AK14: =IF(AJ14="","",MIN(Настройки!$B$11,Настройки!$B$11*VLOOKUP(AJ14,Настройки!$A$16:$B$19,2,FALSE())+IF(AND($B14="ТТМ",AG14="Да"),Настройки!$B$11*Настройки!$A$53,0))) | AO14: =IF(OR($A14="",AL14=""),"",MIN(IF($B14="ТТП",IF(AL14/Настройки!$C$57>=Настройки!$B$23,5,IF(AL14/Настройки!$C$57>=Настройки!$B$24,4,IF(AL14/Настройки!$C$57>=Настройки!$B$25,3,2))),IF($B14="ТТМ",IF(AL14/Настройки!$C$57>=Настройки!$B$29,5,IF(AL14/Настройки!$C$57>=Настройки!$B$30,4,IF(AL14/Настройки!$C$57>=Настройки!$B$31,3,2))),"")),IF($B14<>"ТТП",5,IF(AM14="Да",5,4)),IFERROR(VLOOKUP(AN14,Настройки!$A$35:$B$37,2,FALSE()),5))) | AP14: =IF(AO14="","",MIN(Настройки!$B$57,Настройки!$B$57*VLOOKUP(AO14,Настройки!$A$16:$B$19,2,FALSE())+IF(AND($B14="ТТМ",AM14="Да"),Настройки!$B$57*Настройки!$A$53,0))) | AQ14: =IF($A14="","",SUM(G14,M14,S14,Y14,AE14,AK14)+IF(AP14="",0,AP14)) | AR14: =IF(AQ14="","",VLOOKUP(AQ14,Настройки!$A$48:$B$51,2,TRUE()))
F15: =IF(OR($A15="",C15=""),"",MIN(IF($B15="ТТП",IF(C15/Настройки!$C$6>=Настройки!$B$23,5,IF(C15/Настройки!$C$6>=Настройки!$B$24,4,IF(C15/Настройки!$C$6>=Настройки!$B$25,3,2))),IF($B15="ТТМ",IF(C15/Настройки!$C$6>=Настройки!$B$29,5,IF(C15/Настройки!$C$6>=Настройки!$B$30,4,IF(C15/Настройки!$C$6>=Настройки!$B$31,3,2))),"")),IFERROR(VLOOKUP(D15,Настройки!$A$35:$B$37,2,FALSE()),5),IFERROR(VLOOKUP(E15,Настройки!$A$41:$B$44,2,FALSE()),5))) | G15: =IF(F15="","",Настройки!$B$6*VLOOKUP(F15,Настройки!$A$16:$B$19,2,FALSE())) | L15: =IF(OR($A15="",H15=""),"",MIN(IF($B15="ТТП",IF(H15/Настройки!$C$7>=Настройки!$B$23,5,IF(H15/Настройки!$C$7>=Настройки!$B$24,4,IF(H15/Настройки!$C$7>=Настройки!$B$25,3,2))),IF($B15="ТТМ",IF(H15/Настройки!$C$7>=Настройки!$B$29,5,IF(H15/Настройки!$C$7>=Настройки!$B$30,4,IF(H15/Настройки!$C$7>=Настройки!$B$31,3,2))),"")),IF($B15<>"ТТП",5,IF(I15="Да",5,4)),IFERROR(VLOOKUP(J15,Настройки!$A$35:$B$37,2,FALSE()),5),IFERROR(VLOOKUP(K15,Настройки!$A$41:$B$44,2,FALSE()),5))) | M15: =IF(L15="","",MIN(Настройки!$B$7,Настройки!$B$7*VLOOKUP(L15,Настройки!$A$16:$B$19,2,FALSE())+IF(AND($B15="ТТМ",I15="Да"),Настройки!$B$7*Настройки!$A$53,0))) | R15: =IF(OR($A15="",N15=""),"",MIN(IF($B15="ТТП",IF(N15/Настройки!$C$8>=Настройки!$B$23,5,IF(N15/Настройки!$C$8>=Настройки!$B$24,4,IF(N15/Настройки!$C$8>=Настройки!$B$25,3,2))),IF($B15="ТТМ",IF(N15/Настройки!$C$8>=Настройки!$B$29,5,IF(N15/Настройки!$C$8>=Настройки!$B$30,4,IF(N15/Настройки!$C$8>=Настройки!$B$31,3,2))),"")),IF($B15<>"ТТП",5,IF(O15="Да",5,4)),IFERROR(VLOOKUP(P15,Настройки!$A$35:$B$37,2,FALSE()),5),IFERROR(VLOOKUP(Q15,Настройки!$A$41:$B$44,2,FALSE()),5))) | S15: =IF(R15="","",MIN(Настройки!$B$8,Настройки!$B$8*VLOOKUP(R15,Настройки!$A$16:$B$19,2,FALSE())+IF(AND($B15="ТТМ",O15="Да"),Настройки!$B$8*Настройки!$A$53,0))) | X15: =IF(OR($A15="",T15=""),"",MIN(IF($B15="ТТП",IF(T15/Настройки!$C$9>=Настройки!$B$23,5,IF(T15/Настройки!$C$9>=Настройки!$B$24,4,IF(T15/Настройки!$C$9>=Настройки!$B$25,3,2))),IF($B15="ТТМ",IF(T15/Настройки!$C$9>=Настройки!$B$29,5,IF(T15/Настройки!$C$9>=Настройки!$B$30,4,IF(T15/Настройки!$C$9>=Настройки!$B$31,3,2))),"")),IF($B15<>"ТТП",5,IF(U15="Да",5,4)),IFERROR(VLOOKUP(V15,Настройки!$A$35:$B$37,2,FALSE()),5),IFERROR(VLOOKUP(W15,Настройки!$A$41:$B$44,2,FALSE()),5))) | Y15: =IF(X15="","",MIN(Настройки!$B$9,Настройки!$B$9*VLOOKUP(X15,Настройки!$A$16:$B$19,2,FALSE())+IF(AND($B15="ТТМ",U15="Да"),Настройки!$B$9*Настройки!$A$53,0))) | AD15: =IF(OR($A15="",Z15=""),"",MIN(IF($B15="ТТП",IF(Z15/Настройки!$C$10>=Настройки!$B$23,5,IF(Z15/Настройки!$C$10>=Настройки!$B$24,4,IF(Z15/Настройки!$C$10>=Настройки!$B$25,3,2))),IF($B15="ТТМ",IF(Z15/Настройки!$C$10>=Настройки!$B$29,5,IF(Z15/Настройки!$C$10>=Настройки!$B$30,4,IF(Z15/Настройки!$C$10>=Настройки!$B$31,3,2))),"")),IF($B15<>"ТТП",5,IF(AA15="Да",5,4)),IFERROR(VLOOKUP(AB15,Настройки!$A$35:$B$37,2,FALSE()),5),IFERROR(VLOOKUP(AC15,Настройки!$A$41:$B$44,2,FALSE()),5))) | AE15: =IF(AD15="","",MIN(Настройки!$B$10,Настройки!$B$10*VLOOKUP(AD15,Настройки!$A$16:$B$19,2,FALSE())+IF(AND($B15="ТТМ",AA15="Да"),Настройки!$B$10*Настройки!$A$53,0))) | AJ15: =IF(OR($A15="",AF15=""),"",MIN(IF($B15="ТТП",IF(AF15/Настройки!$C$11>=Настройки!$B$23,5,IF(AF15/Настройки!$C$11>=Настройки!$B$24,4,IF(AF15/Настройки!$C$11>=Настройки!$B$25,3,2))),IF($B15="ТТМ",IF(AF15/Настройки!$C$11>=Настройки!$B$29,5,IF(AF15/Настройки!$C$11>=Настройки!$B$30,4,IF(AF15/Настройки!$C$11>=Настройки!$B$31,3,2))),"")),IF($B15<>"ТТП",5,IF(AG15="Да",5,4)),IFERROR(VLOOKUP(AH15,Настройки!$A$35:$B$37,2,FALSE()),5),IFERROR(VLOOKUP(AI15,Настройки!$A$41:$B$44,2,FALSE()),5))) | AK15: =IF(AJ15="","",MIN(Настройки!$B$11,Настройки!$B$11*VLOOKUP(AJ15,Настройки!$A$16:$B$19,2,FALSE())+IF(AND($B15="ТТМ",AG15="Да"),Настройки!$B$11*Настройки!$A$53,0))) | AO15: =IF(OR($A15="",AL15=""),"",MIN(IF($B15="ТТП",IF(AL15/Настройки!$C$57>=Настройки!$B$23,5,IF(AL15/Настройки!$C$57>=Настройки!$B$24,4,IF(AL15/Настройки!$C$57>=Настройки!$B$25,3,2))),IF($B15="ТТМ",IF(AL15/Настройки!$C$57>=Настройки!$B$29,5,IF(AL15/Настройки!$C$57>=Настройки!$B$30,4,IF(AL15/Настройки!$C$57>=Настройки!$B$31,3,2))),"")),IF($B15<>"ТТП",5,IF(AM15="Да",5,4)),IFERROR(VLOOKUP(AN15,Настройки!$A$35:$B$37,2,FALSE()),5))) | AP15: =IF(AO15="","",MIN(Настройки!$B$57,Настройки!$B$57*VLOOKUP(AO15,Настройки!$A$16:$B$19,2,FALSE())+IF(AND($B15="ТТМ",AM15="Да"),Настройки!$B$57*Настройки!$A$53,0))) | AQ15: =IF($A15="","",SUM(G15,M15,S15,Y15,AE15,AK15)+IF(AP15="",0,AP15)) | AR15: =IF(AQ15="","",VLOOKUP(AQ15,Настройки!$A$48:$B$51,2,TRUE()))
F16: =IF(OR($A16="",C16=""),"",MIN(IF($B16="ТТП",IF(C16/Настройки!$C$6>=Настройки!$B$23,5,IF(C16/Настройки!$C$6>=Настройки!$B$24,4,IF(C16/Настройки!$C$6>=Настройки!$B$25,3,2))),IF($B16="ТТМ",IF(C16/Настройки!$C$6>=Настройки!$B$29,5,IF(C16/Настройки!$C$6>=Настройки!$B$30,4,IF(C16/Настройки!$C$6>=Настройки!$B$31,3,2))),"")),IFERROR(VLOOKUP(D16,Настройки!$A$35:$B$37,2,FALSE()),5),IFERROR(VLOOKUP(E16,Настройки!$A$41:$B$44,2,FALSE()),5))) | G16: =IF(F16="","",Настройки!$B$6*VLOOKUP(F16,Настройки!$A$16:$B$19,2,FALSE())) | L16: =IF(OR($A16="",H16=""),"",MIN(IF($B16="ТТП",IF(H16/Настройки!$C$7>=Настройки!$B$23,5,IF(H16/Настройки!$C$7>=Настройки!$B$24,4,IF(H16/Настройки!$C$7>=Настройки!$B$25,3,2))),IF($B16="ТТМ",IF(H16/Настройки!$C$7>=Настройки!$B$29,5,IF(H16/Настройки!$C$7>=Настройки!$B$30,4,IF(H16/Настройки!$C$7>=Настройки!$B$31,3,2))),"")),IF($B16<>"ТТП",5,IF(I16="Да",5,4)),IFERROR(VLOOKUP(J16,Настройки!$A$35:$B$37,2,FALSE()),5),IFERROR(VLOOKUP(K16,Настройки!$A$41:$B$44,2,FALSE()),5))) | M16: =IF(L16="","",MIN(Настройки!$B$7,Настройки!$B$7*VLOOKUP(L16,Настройки!$A$16:$B$19,2,FALSE())+IF(AND($B16="ТТМ",I16="Да"),Настройки!$B$7*Настройки!$A$53,0))) | R16: =IF(OR($A16="",N16=""),"",MIN(IF($B16="ТТП",IF(N16/Настройки!$C$8>=Настройки!$B$23,5,IF(N16/Настройки!$C$8>=Настройки!$B$24,4,IF(N16/Настройки!$C$8>=Настройки!$B$25,3,2))),IF($B16="ТТМ",IF(N16/Настройки!$C$8>=Настройки!$B$29,5,IF(N16/Настройки!$C$8>=Настройки!$B$30,4,IF(N16/Настройки!$C$8>=Настройки!$B$31,3,2))),"")),IF($B16<>"ТТП",5,IF(O16="Да",5,4)),IFERROR(VLOOKUP(P16,Настройки!$A$35:$B$37,2,FALSE()),5),IFERROR(VLOOKUP(Q16,Настройки!$A$41:$B$44,2,FALSE()),5))) | S16: =IF(R16="","",MIN(Настройки!$B$8,Настройки!$B$8*VLOOKUP(R16,Настройки!$A$16:$B$19,2,FALSE())+IF(AND($B16="ТТМ",O16="Да"),Настройки!$B$8*Настройки!$A$53,0))) | X16: =IF(OR($A16="",T16=""),"",MIN(IF($B16="ТТП",IF(T16/Настройки!$C$9>=Настройки!$B$23,5,IF(T16/Настройки!$C$9>=Настройки!$B$24,4,IF(T16/Настройки!$C$9>=Настройки!$B$25,3,2))),IF($B16="ТТМ",IF(T16/Настройки!$C$9>=Настройки!$B$29,5,IF(T16/Настройки!$C$9>=Настройки!$B$30,4,IF(T16/Настройки!$C$9>=Настройки!$B$31,3,2))),"")),IF($B16<>"ТТП",5,IF(U16="Да",5,4)),IFERROR(VLOOKUP(V16,Настройки!$A$35:$B$37,2,FALSE()),5),IFERROR(VLOOKUP(W16,Настройки!$A$41:$B$44,2,FALSE()),5))) | Y16: =IF(X16="","",MIN(Настройки!$B$9,Настройки!$B$9*VLOOKUP(X16,Настройки!$A$16:$B$19,2,FALSE())+IF(AND($B16="ТТМ",U16="Да"),Настройки!$B$9*Настройки!$A$53,0))) | AD16: =IF(OR($A16="",Z16=""),"",MIN(IF($B16="ТТП",IF(Z16/Настройки!$C$10>=Настройки!$B$23,5,IF(Z16/Настройки!$C$10>=Настройки!$B$24,4,IF(Z16/Настройки!$C$10>=Настройки!$B$25,3,2))),IF($B16="ТТМ",IF(Z16/Настройки!$C$10>=Настройки!$B$29,5,IF(Z16/Настройки!$C$10>=Настройки!$B$30,4,IF(Z16/Настройки!$C$10>=Настройки!$B$31,3,2))),"")),IF($B16<>"ТТП",5,IF(AA16="Да",5,4)),IFERROR(VLOOKUP(AB16,Настройки!$A$35:$B$37,2,FALSE()),5),IFERROR(VLOOKUP(AC16,Настройки!$A$41:$B$44,2,FALSE()),5))) | AE16: =IF(AD16="","",MIN(Настройки!$B$10,Настройки!$B$10*VLOOKUP(AD16,Настройки!$A$16:$B$19,2,FALSE())+IF(AND($B16="ТТМ",AA16="Да"),Настройки!$B$10*Настройки!$A$53,0))) | AJ16: =IF(OR($A16="",AF16=""),"",MIN(IF($B16="ТТП",IF(AF16/Настройки!$C$11>=Настройки!$B$23,5,IF(AF16/Настройки!$C$11>=Настройки!$B$24,4,IF(AF16/Настройки!$C$11>=Настройки!$B$25,3,2))),IF($B16="ТТМ",IF(AF16/Настройки!$C$11>=Настройки!$B$29,5,IF(AF16/Настройки!$C$11>=Настройки!$B$30,4,IF(AF16/Настройки!$C$11>=Настройки!$B$31,3,2))),"")),IF($B16<>"ТТП",5,IF(AG16="Да",5,4)),IFERROR(VLOOKUP(AH16,Настройки!$A$35:$B$37,2,FALSE()),5),IFERROR(VLOOKUP(AI16,Настройки!$A$41:$B$44,2,FALSE()),5))) | AK16: =IF(AJ16="","",MIN(Настройки!$B$11,Настройки!$B$11*VLOOKUP(AJ16,Настройки!$A$16:$B$19,2,FALSE())+IF(AND($B16="ТТМ",AG16="Да"),Настройки!$B$11*Настройки!$A$53,0))) | AO16: =IF(OR($A16="",AL16=""),"",MIN(IF($B16="ТТП",IF(AL16/Настройки!$C$57>=Настройки!$B$23,5,IF(AL16/Настройки!$C$57>=Настройки!$B$24,4,IF(AL16/Настройки!$C$57>=Настройки!$B$25,3,2))),IF($B16="ТТМ",IF(AL16/Настройки!$C$57>=Настройки!$B$29,5,IF(AL16/Настройки!$C$57>=Настройки!$B$30,4,IF(AL16/Настройки!$C$57>=Настройки!$B$31,3,2))),"")),IF($B16<>"ТТП",5,IF(AM16="Да",5,4)),IFERROR(VLOOKUP(AN16,Настройки!$A$35:$B$37,2,FALSE()),5))) | AP16: =IF(AO16="","",MIN(Настройки!$B$57,Настройки!$B$57*VLOOKUP(AO16,Настройки!$A$16:$B$19,2,FALSE())+IF(AND($B16="ТТМ",AM16="Да"),Настройки!$B$57*Настройки!$A$53,0))) | AQ16: =IF($A16="","",SUM(G16,M16,S16,Y16,AE16,AK16)+IF(AP16="",0,AP16)) | AR16: =IF(AQ16="","",VLOOKUP(AQ16,Настройки!$A$48:$B$51,2,TRUE()))
F17: =IF(OR($A17="",C17=""),"",MIN(IF($B17="ТТП",IF(C17/Настройки!$C$6>=Настройки!$B$23,5,IF(C17/Настройки!$C$6>=Настройки!$B$24,4,IF(C17/Настройки!$C$6>=Настройки!$B$25,3,2))),IF($B17="ТТМ",IF(C17/Настройки!$C$6>=Настройки!$B$29,5,IF(C17/Настройки!$C$6>=Настройки!$B$30,4,IF(C17/Настройки!$C$6>=Настройки!$B$31,3,2))),"")),IFERROR(VLOOKUP(D17,Настройки!$A$35:$B$37,2,FALSE()),5),IFERROR(VLOOKUP(E17,Настройки!$A$41:$B$44,2,FALSE()),5))) | G17: =IF(F17="","",Настройки!$B$6*VLOOKUP(F17,Настройки!$A$16:$B$19,2,FALSE())) | L17: =IF(OR($A17="",H17=""),"",MIN(IF($B17="ТТП",IF(H17/Настройки!$C$7>=Настройки!$B$23,5,IF(H17/Настройки!$C$7>=Настройки!$B$24,4,IF(H17/Настройки!$C$7>=Настройки!$B$25,3,2))),IF($B17="ТТМ",IF(H17/Настройки!$C$7>=Настройки!$B$29,5,IF(H17/Настройки!$C$7>=Настройки!$B$30,4,IF(H17/Настройки!$C$7>=Настройки!$B$31,3,2))),"")),IF($B17<>"ТТП",5,IF(I17="Да",5,4)),IFERROR(VLOOKUP(J17,Настройки!$A$35:$B$37,2,FALSE()),5),IFERROR(VLOOKUP(K17,Настройки!$A$41:$B$44,2,FALSE()),5))) | M17: =IF(L17="","",MIN(Настройки!$B$7,Настройки!$B$7*VLOOKUP(L17,Настройки!$A$16:$B$19,2,FALSE())+IF(AND($B17="ТТМ",I17="Да"),Настройки!$B$7*Настройки!$A$53,0))) | R17: =IF(OR($A17="",N17=""),"",MIN(IF($B17="ТТП",IF(N17/Настройки!$C$8>=Настройки!$B$23,5,IF(N17/Настройки!$C$8>=Настройки!$B$24,4,IF(N17/Настройки!$C$8>=Настройки!$B$25,3,2))),IF($B17="ТТМ",IF(N17/Настройки!$C$8>=Настройки!$B$29,5,IF(N17/Настройки!$C$8>=Настройки!$B$30,4,IF(N17/Настройки!$C$8>=Настройки!$B$31,3,2))),"")),IF($B17<>"ТТП",5,IF(O17="Да",5,4)),IFERROR(VLOOKUP(P17,Настройки!$A$35:$B$37,2,FALSE()),5),IFERROR(VLOOKUP(Q17,Настройки!$A$41:$B$44,2,FALSE()),5))) | S17: =IF(R17="","",MIN(Настройки!$B$8,Настройки!$B$8*VLOOKUP(R17,Настройки!$A$16:$B$19,2,FALSE())+IF(AND($B17="ТТМ",O17="Да"),Настройки!$B$8*Настройки!$A$53,0))) | X17: =IF(OR($A17="",T17=""),"",MIN(IF($B17="ТТП",IF(T17/Настройки!$C$9>=Настройки!$B$23,5,IF(T17/Настройки!$C$9>=Настройки!$B$24,4,IF(T17/Настройки!$C$9>=Настройки!$B$25,3,2))),IF($B17="ТТМ",IF(T17/Настройки!$C$9>=Настройки!$B$29,5,IF(T17/Настройки!$C$9>=Настройки!$B$30,4,IF(T17/Настройки!$C$9>=Настройки!$B$31,3,2))),"")),IF($B17<>"ТТП",5,IF(U17="Да",5,4)),IFERROR(VLOOKUP(V17,Настройки!$A$35:$B$37,2,FALSE()),5),IFERROR(VLOOKUP(W17,Настройки!$A$41:$B$44,2,FALSE()),5))) | Y17: =IF(X17="","",MIN(Настройки!$B$9,Настройки!$B$9*VLOOKUP(X17,Настройки!$A$16:$B$19,2,FALSE())+IF(AND($B17="ТТМ",U17="Да"),Настройки!$B$9*Настройки!$A$53,0))) | AD17: =IF(OR($A17="",Z17=""),"",MIN(IF($B17="ТТП",IF(Z17/Настройки!$C$10>=Настройки!$B$23,5,IF(Z17/Настройки!$C$10>=Настройки!$B$24,4,IF(Z17/Настройки!$C$10>=Настройки!$B$25,3,2))),IF($B17="ТТМ",IF(Z17/Настройки!$C$10>=Настройки!$B$29,5,IF(Z17/Настройки!$C$10>=Настройки!$B$30,4,IF(Z17/Настройки!$C$10>=Настройки!$B$31,3,2))),"")),IF($B17<>"ТТП",5,IF(AA17="Да",5,4)),IFERROR(VLOOKUP(AB17,Настройки!$A$35:$B$37,2,FALSE()),5),IFERROR(VLOOKUP(AC17,Настройки!$A$41:$B$44,2,FALSE()),5))) | AE17: =IF(AD17="","",MIN(Настройки!$B$10,Настройки!$B$10*VLOOKUP(AD17,Настройки!$A$16:$B$19,2,FALSE())+IF(AND($B17="ТТМ",AA17="Да"),Настройки!$B$10*Настройки!$A$53,0))) | AJ17: =IF(OR($A17="",AF17=""),"",MIN(IF($B17="ТТП",IF(AF17/Настройки!$C$11>=Настройки!$B$23,5,IF(AF17/Настройки!$C$11>=Настройки!$B$24,4,IF(AF17/Настройки!$C$11>=Настройки!$B$25,3,2))),IF($B17="ТТМ",IF(AF17/Настройки!$C$11>=Настройки!$B$29,5,IF(AF17/Настройки!$C$11>=Настройки!$B$30,4,IF(AF17/Настройки!$C$11>=Настройки!$B$31,3,2))),"")),IF($B17<>"ТТП",5,IF(AG17="Да",5,4)),IFERROR(VLOOKUP(AH17,Настройки!$A$35:$B$37,2,FALSE()),5),IFERROR(VLOOKUP(AI17,Настройки!$A$41:$B$44,2,FALSE()),5))) | AK17: =IF(AJ17="","",MIN(Настройки!$B$11,Настройки!$B$11*VLOOKUP(AJ17,Настройки!$A$16:$B$19,2,FALSE())+IF(AND($B17="ТТМ",AG17="Да"),Настройки!$B$11*Настройки!$A$53,0))) | AO17: =IF(OR($A17="",AL17=""),"",MIN(IF($B17="ТТП",IF(AL17/Настройки!$C$57>=Настройки!$B$23,5,IF(AL17/Настройки!$C$57>=Настройки!$B$24,4,IF(AL17/Настройки!$C$57>=Настройки!$B$25,3,2))),IF($B17="ТТМ",IF(AL17/Настройки!$C$57>=Настройки!$B$29,5,IF(AL17/Настройки!$C$57>=Настройки!$B$30,4,IF(AL17/Настройки!$C$57>=Настройки!$B$31,3,2))),"")),IF($B17<>"ТТП",5,IF(AM17="Да",5,4)),IFERROR(VLOOKUP(AN17,Настройки!$A$35:$B$37,2,FALSE()),5))) | AP17: =IF(AO17="","",MIN(Настройки!$B$57,Настройки!$B$57*VLOOKUP(AO17,Настройки!$A$16:$B$19,2,FALSE())+IF(AND($B17="ТТМ",AM17="Да"),Настройки!$B$57*Настройки!$A$53,0))) | AQ17: =IF($A17="","",SUM(G17,M17,S17,Y17,AE17,AK17)+IF(AP17="",0,AP17)) | AR17: =IF(AQ17="","",VLOOKUP(AQ17,Настройки!$A$48:$B$51,2,TRUE()))
